Creating a complex robotic arm model with 7 degrees of freedom (DoF) or higher in MuJoCo can be quite involved. I'll provide you with an outline and an example of a 7-DoF robotic arm defined in an XML file for MuJoCo. You can then use `mujoco_py` to load and simulate this model.

First, create a new XML file called `robotic_arm_7dof.xml` with the following content:

```xml
<mujoco model="7dof_robotic_arm">
    <compiler angle="degree" coordinate="local"/>
    <option integrator="RK4" timestep="0.002"/>

    <worldbody>
        <light cutoff="100" diffuse="1 1 1" dir="-1 -.2 -.4" directional="true" exponent="1" pos="0 0 0" specular=".1 .1 .1"/>
        
        <body name="base" pos="0 0 0">
            <joint name="joint1" type="hinge" axis="0 0 1" limited="true" range="-180 180"/>
            <geom type="cylinder" size="0.05 0.15" rgba="0.8 0.6 0.4 1"/>
            <body name="link1" pos="0 0 0.15">
                <joint name="joint2" type="hinge" axis="0 1 0" limited="true" range="-90 90"/>
                <geom type="capsule" fromto="0 0 0 0.3 0 0" size="0.05" rgba="0.8 0.6 0.4 1"/>
                <body name="link2" pos="0.3 0 0">
                    <joint name="joint3" type="hinge" axis="0 0 1" limited="true" range="-180 180"/>
                    <geom type="capsule" fromto="0 0 0 0.3 0 0" size="0.05" rgba="0.8 0.6 0.4 1"/>
                    <body name="link3" pos="0.3 0 0">
                        <joint name="joint4" type="hinge" axis="0 1 0" limited="true" range="-120 120"/>
                        <geom type="capsule" fromto="0 0 0 0.3 0 0" size="0.05" rgba="0.8 0.6 0.4 1"/>
                        <body name="link4" pos="0.3 0 0">
                            <joint name="joint5" type="hinge" axis="0 0 1" limited="true" range="-180 180"/>
                            <geom type="capsule" fromto="0 0 0 0.3 0 0" size="0.05" rgba="0.8 0.6 0.4 1"/>
                            <body name="link5" pos="0.3 0 0">
                                <joint name="joint6" type="hinge" axis="0 1 0" limited="true" range="-90 90"/>
                                <geom type="capsule" fromto="0 0 0 0.3 0 0" size="0.05" rgba="0.8 0.6 0.4 1"/>
                                <body name="link6" pos="0.3 0 0">
                                    <joint name="joint7" type="hinge" axis="0 0 1" limited="true" range="-180 180"/>
                                    <geom type="capsule" fromto="0 0 0 0.3 0 0" size="0.05" rgba="0.8 0.6 0.4 1"/>
                                    <body name="end_effector" pos="0.3 0 0"/>
                                </body>
                            </body>
                        </body>
                    </body>
                </body>
            </body>
        </body>
    </worldbody>

